<mujoco>
    <body mocap="true" name="robot0:mocap" pos="0 0 0">
      <!-- <geom conaffinity="0" contype="0" pos="0 0 0" rgba="0.5 0 0 0.15" size="1 0.005 0.005" type="box"></geom>
      <geom conaffinity="0" contype="0" pos="0 0 0" rgba="0 0 0.5 0.15" size="0.005 1 0.001" type="box"></geom>
      <geom conaffinity="0" contype="0" pos="0 0 0" rgba="0 0.5 0 0.15" size="0.005 0.005 1" type="box"></geom> -->
    </body>
    <body childclass="ned2:robot" name="robot0:base_link" pos="0 0 0">
      <site name="robot0:base_center" size="0.01" pos="0 0 0" rgba="1 0 0 1" type="sphere"/>
      <geom pos="0 0 0" quat="0.707107 -0.707107 0 0" type="mesh" mesh="robot0:base_link" name="robot0:base_link" contype="1" conaffinity="0" mass="0.71142" group="1" class="ned2:grey"/>
      
      <!-- Shoulder (connecting base with arm) -->
      <body name="robot0:shoulder_link" pos="0 0 0.1013">
        <inertial pos="-0.031951 0.0080419 0.030675" quat="0.500342 0.499382 0.516882 0.482813" mass="0.35056" diaginertia="0.000326411 0.000300927 0.000238682" />
        <joint name="robot0:shoulder_joint" pos="0 0 0" axis="0 0 1" range="-2.99987 2.99987" actuatorfrcrange="-10 10" />
        <geom quat="0.707107 0 0 -0.707107" type="mesh" mesh="robot0:shoulder_link" name="robot0:shoulder_link" contype="1" conaffinity="0" group="1" class="ned2:blue" />
        
        <!-- Arm (connecting shoulder with elbow) -->
        <body name="robot0:arm_link" pos="0 0 0.065" quat="0.707107 0.707107 0 0">
          <inertial pos="-0.00096976 0.086432 0.0038832" quat="0.690493 0.722981 0.0220291 -0.00569833" mass="1.0838" diaginertia="0.00819788 0.00792912 0.0011765" />
          <joint name="robot0:arm_joint" pos="0 0 0" axis="0 0 1" range="-1.8326 0.610167" actuatorfrcrange="-10 10" />
          <geom pos="0 0 0" quat="0 0 1 0" type="mesh" mesh="robot0:arm_link" name="robot0:arm_link" contype="1" conaffinity="0" group="1" class="ned2:grey"/>
          
          <!-- Elbow (connecting arm with forearm) -->
          <body name="robot0:elbow_link" pos="0.012 0.221 0" quat="0.707107 0 0 0.707107">
            <inertial pos="-0.019703 0.037336 -1.7431e-09" quat="-0.0467018 0.705563 0.0467058 0.705563" mass="0.22126" diaginertia="0.00022753 0.000210147 0.000115903" />
            <joint name="robot0:elbow_joint" pos="0 0 0" axis="0 0 1" range="-1.34006 1.5701" actuatorfrcrange="-7 7" />
            <geom quat="0 0.707107 0.707107 0" type="mesh" mesh="robot0:elbow_link" name="robot0:elbow_link" contype="1" conaffinity="0" group="1" class="ned2:blue"/>
            
            <!-- Forarm (connecting elbow with wrist) -->
            <body name="robot0:forearm_link" pos="0.0325 -0.065 0" quat="0.707107 0.707107 0 0">
              <inertial pos="-0.0049532 7.8351e-06 0.08106" quat="0.705459 -0.041804 -0.0416797 0.706288" mass="0.35686" diaginertia="0.0014781 0.00138253 0.000221016" />
              <joint name="robot0:forearm_joint" pos="0 0 0" axis="0 0 1" range="-2.09003 2.09003" actuatorfrcrange="-7 7" />
              <geom quat="0.707107 0 0 -0.707107" type="mesh" mesh="robot0:forearm_link" name="robot0:forearm_link" contype="1" conaffinity="0"  group="1" class="ned2:blue"/>
              
              <!-- Wrist (connecting forarm with hand) -->
              <body name="robot0:wrist_link" pos="0 0 0.17" quat="0.707107 -0.707107 0 0">
                <inertial pos="-0.0162768 0.0351379 0" quat="0.618477 0.618477 0.342763 0.342763" mass="0.23495" diaginertia="0.00156403 0.00156324 0.00150233" />
                <joint name="robot0:wrist_joint" pos="0 0 0" axis="0 0 1" range="-1.92004 1.92283" actuatorfrcrange="-6 6" />
                <geom quat="0.707107 0 0 -0.707107" type="mesh" mesh="robot0:wrist_link" name="robot0:wrist_link" contype="1" conaffinity="0"  group="1" class="ned2:grey"/>
                
                <!-- Camera Block (where camera is mounted irl, has mesh) -->
                <geom size="0.005 0.0185 0.0185" pos="0.0385 0 0" quat="0.766044 0 0 -0.642788" type="box" name="robot0:camera_link" contype="1" conaffinity="0"  group="1" class="ned2:dark"/>
                
                <!-- Hand (connecting gripper-module with wrist) -->
                <body name="robot0:hand_link" pos="0.00925 -0.0197 0" quat="0.707107 0.707107 0 0">
                  <inertial pos="-0.00051755 0.0029705 0.0115341" quat="0.418011 0.906052 0.0275832 0.0597875" mass="0.0080027" diaginertia="0.00150187 0.00150187 0.001501" />
                  <joint name="robot0:hand_joint" pos="0 0 0" axis="0 0 1" range="-2.53003 2.53003" actuatorfrcrange="-5 5" />
                  <geom quat="0.707107 0 0 -0.707107" type="mesh" mesh="robot0:hand_link" name="robot0:hand_link" contype="1" conaffinity="0"  group="1" class="ned2:grey"/>
                 
                  <!-- The gripper base (this part + gripper teeth are swappable irl) -->
                  <body name="robot0:base_gripper" pos="-0.007 0 0.0315" quat="0.707107 -0.707107 0 0">
                      <geom  type="mesh" mesh="robot0:base_gripper" name="robot0:base_gripper" contype="1" conaffinity="0"  group="1" class="ned2:dark"/>
                  </body>

                    <!-- Camera Gizmo (where camera records virtually, no mesh/mass) -->
                    <body name="robot0:gripper_camera_link" pos="0.03 0 -0.02">
                      <body name="robot0:gripper_camera_rgb_frame" pos="0 0 0">
                          <body name="robot0:gripper_camera_rgb_optical_frame" pos="0 0 0" quat="1 1 1 1">
                              <camera euler="1.75 0 0" fovy="69.33" name="gripper_camera_rgb" pos="0 0 0"></camera>
                          </body>
                      </body>
                    </body>

                    <!-- Right gripper tooth -->
                    <body childclass="ned2:robotGripper" name="robot0:r_gripper_finger_link" pos="0.00755 0.0096137 0.1111" quat="1 1.8366e-06 0 0">
                      <inertial pos="-0.0049739 0.0067393 -0.023929" quat="0.703927 0.0215488 -0.114093 0.700718" mass="0.067248" diaginertia="1.33992e-06 1.19147e-06 3.87144e-07" />
                      <joint name="robot0:r_gripper_finger_joint" pos="0 0 0" axis="0 1 0" type="slide" range="-0.01 0.01" actuatorfrcrange="-1 1" />
                      <geom type="mesh" mesh="robot0:r_gripper_finger_link" name="robot0:r_gripper_finger_link" group="1" class="ned2:dark" />
                    </body>
                    <!-- Left gripper tooth -->
                    <body childclass="ned2:robotGripper" name="robot0:l_gripper_finger_link" pos="0.00755 -0.011066 0.1111" quat="1 1.8366e-06 0 0">
                      <inertial pos="-0.0049739 -0.0067393 -0.023929" quat="0.700718 -0.114093 0.0215488 0.703927" mass="0.067248" diaginertia="1.33992e-06 1.19147e-06 3.87144e-07" />
                      <joint name="robot0:l_gripper_finger_joint" pos="0 0 0" axis="0 -1 0" type="slide" range="-0.01 0.01" actuatorfrcrange="-1 1" />
                      <geom type="mesh" mesh="robot0:l_gripper_finger_link" name="robot0:l_gripper_finger_link" group="1" class="ned2:dark" />
                    </body>
                    <!-- Grip-Site between both grippers (slightly set forwards) -->
                    <site name="robot0:grip" pos="0 0 0.099" rgba="1 0 0 0.1" size="0.01 0.01 0.01"></site>
                
                </body>
              </body>
            </body>
          </body>
        </body>
      </body>
    
    <body name="robot0:external_camera_body_0" pos="0 0 0">
        <camera euler="0 0.75 1.57" fovy="43.3" name="external_camera_0" pos="0.75 0 0.95"></camera>
    </body>
    
    </body>

</mujoco>